File: Dataset-in-situ-monitoring-and-structural-validation-of-FFF/Tensile_test_results/test_10202021/Test Run 1 10-21-21 8 40 04 AM/DAQ- Crosshead, … - (Timed).txt
File Path: C:\Users\MEUser\Desktop\Fu\test_10202021\Test Run 1 10-21-21 8 40 04 AM\DAQ- Crosshead, … - (Timed).txt
Test: MTS EM Tension (Extensometer) 68
Test Run: Test Run 1
Date: 10/21/2021 8:38:06 AM


Crosshead 	Load 	Time 	Extensometer
in	lbf	sec	in
0.00346096449780945	93.3701560226584	0.127000004053116	0.00135355455893473
0.00685627350407675	166.717510881806	0.226999998092651	0.00318957528917075
0.0102281344478847	232.110541083304	0.326999992132187	0.00485957427844992
0.0135859270125452	289.605263626067	0.426999986171722	0.00637601733328701
0.0169366842418117	336.50076042064	0.52700001001358	0.00783466235789522
0.0202850971231604	363.305878900533	0.626999974250793	0.00919277713758739
0.0236288201628532	373.822283189949	0.726999998092651	0.0107697681908855
0.0269608191713163	384.254658550682	0.827000021934509	0.0124060038722846
0.0302951625276973	394.216806709265	0.926999986171722	0.0139857242690531
0.0336341968715543	403.773958483295	1.02699995040894	0.0155797857501522
0.0369708845758532	413.164012887386	1.12699997425079	0.0171810005861151
0.0403052302238744	422.431975618155	1.22699999809265	0.01878022513257
0.0436395712886152	431.725734296986	1.32700002193451	0.020363883713011
0.0469692236575203	440.859887407814	1.42700004577637	0.021954722002178
0.0503035693055415	449.711163249909	1.52699995040894	0.0235486723387277
0.0536402570098404	458.330412771946	1.62699997425079	0.025136091500726
0.0569769447141393	466.892170260805	1.72699999809265	0.0267318316082668
0.0603089437226024	475.085567099857	1.82700002193451	0.0283328860294162
0.0636409427310655	483.149819543617	1.92700004577637	0.029933731911308
0.0669752883790868	491.06862674831	2.02699995040894	0.0315339453005063
0.0703143227229437	498.626235795158	2.12700009346008	0.0331377657313692
0.0736416330355711	505.852888316885	2.22699999809265	0.0347366270528534
0.0769736274607538	512.809067578946	2.32699990272522	0.0363358642033294
0.080307973108775	519.792305143972	2.42700004577637	0.037969427832263
0.0836376254776801	526.538165101844	2.52699995040894	0.0395787069500666
0.0869719711257013	532.95142198472	2.62700009346008	0.0412026044406642
0.0903063167737225	539.03245998757	2.72699999809265	0.0428377538846116
0.0936406624217437	545.052740299988	2.82699990272522	0.0444720875046502
0.0969773455427622	550.97186756501	2.92700004577637	0.0461167839216435
0.100309344551225	556.709599918669	3.02699995040894	0.0477727460418278
0.10363899692013	562.327024361373	3.12700009346008	0.049407964234981
0.106970995928594	567.616785378708	3.22699999809265	0.0510706316943713
0.110302994937057	572.47015579385	3.32699990272522	0.0527347062208404
0.11363499394552	577.626546271212	3.42700004577637	0.0544170267865296
0.116971686233099	582.333977482325	3.52699995040894	0.056092880343593
0.120308378520678	587.131749396647	3.62700009346008	0.0577829512364165
0.123640368362581	591.535117730618	3.72699999809265	0.0594656934639014
0.126972367371044	595.954457598389	3.82699990272522	0.0611527485582303
0.130309059658623	599.949097368087	3.92700004577637	0.0628500381176631
0.133645751946202	603.924966469196	4.02699995040894	0.0645404115069922
0.136973057675549	608.185688698891	4.1269998550415	0.0662363764983932
0.140042434717844	611.545363951323	4.22700023651123	0.0679357652002432
0.139913470374318	591.701419268116	4.3270001411438	0.0680558471463797
0.139875951641071	588.381370982705	4.42700004577637	0.0680640420517114
0.13983140215571	584.962859014696	4.52699995040894	0.06805336300841
0.139793883422463	582.344076321566	4.6269998550415	0.0680430002114552
0.139768088720446	580.211794231863	4.72700023651123	0.068039988996241
0.139751680576661	578.599657248057	4.8270001411438	0.0680308591017104
0.139742294018428	577.649488199487	4.92700004577637	0.0680276003893553
0.139735263266315	576.886037906881	5.02699995040894	0.06802706414555
0.139730569987199	576.275277672795	5.1269998550415	0.0680280633006744
0.139730569987199	575.871049678184	5.22700023651123	0.0680245250082157
0.139730569987199	575.647118895018	5.3270001411438	0.0680299057793899
0.139730569987199	575.26385696883	5.42700004577637	0.0680234479373248
0.139730569987199	574.928454759044	5.52699995040894	0.0680282420486095
0.139728232514201	574.753371622207	5.6269998550415	0.0680268991474561
0.139728232514201	574.419012227342	5.72700023651123	0.0680328665785198
0.139728232514201	574.398595008877	5.8270001411438	0.0680269862297834
0.139730569987199	574.167144981277	5.92700004577637	0.068032939911006
0.139730569987199	574.02916410165	6.02699995040894	0.0680306116045695
0.139730569987199	573.90386165607	6.1269998550415	0.0680340169818969
0.139730569987199	573.78706638485	6.22700023651123	0.0680328207457159
0.139730569987199	573.591895339522	6.3270001411438	0.068034846555647
0.139730569987199	573.420105302437	6.42700004577637	0.068028686626807
0.139732916626757	573.401663943823	6.52699995040894	0.0680292274538926
0.139732916626757	573.195076819353	6.6269998550415	0.0680339894822146
0.139732916626757	573.120927189928	6.72700023651123	0.0680266974831191
0.139732916626757	573.128885514329	6.8270001411438	0.0680255195800596
0.139732916626757	572.918950405111	6.92700004577637	0.0680277103880846
0.139732916626757	572.797709449226	7.02699995040894	0.0680317253417035
0.139732916626757	572.700617891525	7.1269998550415	0.068026152072753
0.139732916626757	572.746117553104	7.22700023651123	0.0680374544421871
0.139732916626757	572.620101602578	7.3270001411438	0.0680301486932504
0.139732916626757	572.488103187501	7.42700004577637	0.0680356577962754
0.139732916626757	572.4921097922	7.52699995040894	0.0680307674361026
0.139732916626757	572.35709270235	7.6269998550415	0.0680323440845557
0.139732916626757	572.340188123621	7.72700023651123	0.0680324953328085
0.139732916626757	572.145236618276	7.8270001411438	0.0680330361598941
0.139732916626757	572.152810747707	7.92700004577637	0.0680328436621179
0.139732916626757	572.098639256779	8.02700042724609	0.0680347915562823
0.139732916626757	572.102920286458	8.1269998550415	0.0680368036163722
0.139732916626757	572.011262343348	8.22700023651123	0.0680338703169245
0.139732916626757	571.96175607707	8.32699966430664	0.0680359877924633
0.139732916626757	571.990296274924	8.42700004577637	0.0680320003385267
0.139732916626757	571.770426981453	8.52700042724609	0.068035369049611
0.139732916626757	571.68826414263	8.6269998550415	0.0680342232295143
0.139732916626757	571.683379377997	8.72700023651123	0.0680298232803429
0.139732916626757	571.611095838431	8.82699966430664	0.0680355615473873
0.139732916626757	571.5689441616	8.92700004577637	0.0680371748620835
0.139732916626757	571.539306263828	9.02700042724609	0.0680373765264205
0.139732916626757	571.458789974881	9.1269998550415	0.0680390081742382
0.139732916626757	571.431182821956	9.22700023651123	0.0680373398601774
0.139735263266315	571.414497783211	9.32699966430664	0.068037619440281
0.139735263266315	571.34759297324	9.42700004577637	0.0680359465429398
0.139735263266315	571.313454505807	9.52700042724609	0.0680357998779674
0.139735263266315	571.292488437383	9.6269998550415	0.0680404564908405
0.139732916626757	571.249787910593	9.72700023651123	0.0680390310906402
0.139732916626757	571.1632342721	9.82699966430664	0.0680377111058888
0.139732916626757	571.140731423791	9.92700004577637	0.0680371244459992
0.139732916626757	571.104232901535	10.0270004272461	0.0680397644155021
0.139735263266315	571.088316252732	10.1269998550415	0.0680384994301153
0.139735263266315	570.966471561891	10.2270002365112	0.0680404885738032
0.139732916626757	571.00467151902	10.3269996643066	0.0680370236138307
0.139732916626757	570.992212624956	10.4270000457764	0.068036588202194
0.139732916626757	570.975747126194	10.5270004272461	0.0680411898157024
0.139735263266315	570.858677429995	10.6269998550415	0.0680398056650256
0.139732916626757	570.842047276245	10.7270002365112	0.0680346678077119
0.139732916626757	570.772837296448	10.8269996643066	0.0680401356612134
0.139732916626757	570.749895368173	10.9270000457764	0.0680365332028293
0.139735263266315	570.777941601064	11.0270004272461	0.0680364277873804
0.139732916626757	570.695559222258	11.1269998550415	0.0680393794199496
0.139732916626757	570.7136163859	11.2270002365112	0.0680386460950877
0.141854984612446	646.952772489528	11.3269996643066	0.0685832452204988
0.145294846541534	629.896985596717	11.4270000457764	0.0689174076102263
0.148694843097817	629.614766947934	11.5270004272461	0.0719038410273593
0.152066707479086	629.184523465278	11.6269998550415	0.0751454348301911
0.15541980791045	629.389244499887	11.7270002365112	0.0784248223630931
0.158770570868817	629.214984637988	11.8269996643066	0.0807116776118128
0.162102560710719	628.290666422474	11.9270000457764	0.0810479712269203
0.165436915525301	638.591372678106	12.0270004272461	0.0814104262064761
0.168768905367204	642.032003299453	12.1269998550415	0.0821833872771639
0.172105606821344	644.251332992612	12.2270002365112	0.0840431541263119
0.175437596663246	645.717091692421	12.3269996643066	0.0864557654222869
0.178774279784265	649.00777650504	12.4270000457764	0.0891509542872352
0.182110981238405	650.337475300078	12.5270004272461	0.0908127692564735
0.185445317719865	653.336117049652	12.6269998550415	0.0915633914185556
0.188777325894889	656.281904548199	12.7270002365112	0.0921421222330078
0.192111662376349	657.814732712966	12.8269996643066	0.0940716282765227
0.195443652218252	661.112607460045	12.9270000457764	0.0968867890888781
0.198775660393276	663.679908027045	13.0270004272461	0.0996163892229711
0.202107650235178	666.457143703262	13.1269998550415	0.102212753396217
0.205444351689318	666.588593268381	13.2270002365112	0.103493587766576
0.208781034810337	669.009405781393	13.3269996643066	0.103939476782295
0.212110696345802	670.7811483332	13.4270000457764	0.104467379017256
0.215440339548147	673.323366457086	13.5270004272461	0.106515784520568
0.218772347723171	675.779579792437	13.6269998550415	0.109141710852309
0.222106684204631	677.260267211124	13.7270002365112	0.11173386757416
0.225441020686091	677.874320544962	13.8269996643066	0.113644398836874
0.228775375500673	679.603527224967	13.9270000457764	0.115417945015384
0.232112058621692	682.066985379773	14.0270004272461	0.117562196078146
0.235444066796716	683.317759550745	14.1269998550415	0.118458630722456
0.23877370999906	685.013047303299	14.2270002365112	0.119269963016543
0.242103371534526	686.823648432185	14.3269996643066	0.121109398433895
0.245435361376428	687.621511617205	14.4270000457764	0.123118387725879
0.248774409470126	688.975030500453	14.5270004272461	0.124671404785293
0.252106399312029	690.027011216369	14.6269998550415	0.126743029187045
0.255440735793489	691.367741895578	14.7270002365112	0.12938771030213
0.258782112193624	693.402712887596	14.8269996643066	0.131902217087666
0.26211177372909	694.327305528089	14.9270000457764	0.133612715661174
0.265443781904114	695.56929809972	15.0270004272461	0.13505238819662
0.268775771746016	696.787031503176	15.1269998550415	0.13683493593781
0.27210777992104	697.120787163085	15.2270002365112	0.138033555424589
0.2754421164025	697.89570841983	15.3269996643066	0.137627641780405
0.278776452883961	699.013112050827	15.4270000457764	0.138996484300752
0.282110807698543	700.507795143463	15.5270004272461	0.140871036812428
0.285442797540445	701.890238419536	15.6269998550415	0.14301611286566
0.288772459075911	702.878552540238	15.7270002365112	0.145257731136961
0.292104448917813	703.169333248378	15.8269996643066	0.146815725638876
0.295443497011511	703.870379300676	15.9270000457764	0.147590272524577
0.298777833492972	704.821920474143	16.0270004272461	0.148557555517108
0.302107495028438	705.431967203282	16.1270008087158	0.149962358455372
0.30543948487034	706.633509532955	16.2269992828369	0.151597608731488
0.30877618632448	707.880496639211	16.3269996643066	0.153653677479606
0.312110504472819	708.473419249637	16.4270000457764	0.156068195420222
0.315442512647843	709.146803264015	16.5270004272461	0.158507417242123
0.318781560741541	709.061347325439	16.6270008087158	0.160546830349316
0.322113532250322	709.704654362077	16.7269992828369	0.161778321123029
0.325445540425346	710.4891804931	16.8269996643066	0.162796836023725
0.32877754860037	711.21519921852	16.9270000457764	0.163973107435337
0.332104863496277	711.524037090303	17.0270004272461	0.165366461339194
0.335441528284174	712.161032352416	17.1270008087158	0.16705538182864
0.338773536459198	712.617565748096	17.2269992828369	0.168798770022205
0.342103197994664	712.865755699438	17.3269996643066	0.170219696940869
0.345439899448804	713.459282044819	17.4270000457764	0.1715497282429
0.348774217597143	714.015761017985	17.5270004272461	0.172959068628747
0.352108572411725	714.390351114825	17.6270008087158	0.174398163670865
0.355440580586749	714.727893839449	17.7269992828369	0.175945405796992
0.358777245374646	715.387227294883	17.8269996643066	0.177564825422651
0.362111600189228	715.848371030216	17.9270000457764	0.179248190976269
0.365443608364252	716.33624375854	18.0270004272461	0.18090766847251
0.368775616539276	716.684159747385	18.1270008087158	0.18219538693001
0.372107588048056	716.513522295213	18.2269992828369	0.183742464058043
0.37543959622308	716.992064574237	18.3269996643066	0.184838564729127
0.378769257758546	717.338334013206	18.4270000457764	0.185719416220122
0.382103612573128	717.619784272048	18.5270004272461	0.18660776595783
0.385442624000583	717.861003828914	18.6270008087158	0.18748737079656
0.388779325454723	718.001783843331	18.7269992828369	0.188120395150476
0.392113680269305	718.080598697406	18.8269996643066	0.187763357608337
0.395445651778086	718.242893630205	18.9270000457764	0.188217524028435
0.398780006592668	718.288228636797	19.0270004272461	0.188920580906661
0.402109668128134	718.175549740267	19.1270008087158	0.189661624012735
0.4054393296636	718.085648117026	19.2269992828369	0.190347466089829
0.408773647811938	717.90348481572	19.3269996643066	0.190901383024266
0.41210800262652	717.433724136035	19.4270000457764	0.191315326575689
0.415440010801544	717.173185060621	19.5270004272461	0.191586088447824
0.418771982310325	716.539812208236	19.6270008087158	0.191747658248023
0.422108683764465	715.493265106912	19.7269992828369	0.191809422534516
0.425443038579047	714.514994940454	19.8269996643066	0.19180425259424
0.428777393393629	713.241004416228	19.9270000457764	0.191751618202277
0.432111711541968	711.568439051965	20.0270004272461	0.191683583988214
0.435443719716992	709.57732117165	20.1270008087158	0.191631536256141
0.438773381252458	706.857879396087	20.2269992828369	0.191556938784564
0.442107699400797	703.782837732257	20.3269996643066	0.1914843946226
0.445444400854937	699.679031705766	20.4270000457764	0.191416855402819
0.448778755669519	694.888175300925	20.5270004272461	0.191334759684529
0.452113073817858	688.732987668648	20.6270008087158	0.191241810758283
0.455445081992882	681.290691998132	20.7269992828369	0.191154196770407
0.458781783447022	672.099485934092	20.8269996643066	0.191067921100404
0.462118484901162	661.007667347934	20.9270000457764	0.190977465478689
0.465448109770384	647.360128928904	21.0270004272461	0.190861343486807
0.46877777130585	630.781347535234	21.1270008087158	0.190747916463792
0.47211447275999	610.355073045805	21.2269992828369	0.19060051816655
0.475448790908329	584.371912264121	21.3269996643066	0.190429983469914
0.478804265478934	335.213871922384	21.4270000457764	0.188644337431183
0.481416405303272	55.2860919934874	21.503999710083	0.186476115811998